Traceback (most recent call last):
  File "nengo_omnibot_init_right_dvs.py", line 8, in <module>
    omnirob_right_cam.connect(nstbot.Serial('/home/caxenie/dev/ttyUSB1', baud=12000000))
  File "/media/data_warehouse/research/devel/neuromorphic_sensorimotor_adaptation/omnirob/nstbot/connection.py", line 4, in __init__
    self.conn = serial.Serial(port, baudrate=baud, rtscts=True, timeout=0)
  File "/usr/local/lib/python2.7/dist-packages/serial/serialutil.py", line 182, in __init__
    self.open()
  File "/usr/local/lib/python2.7/dist-packages/serial/serialposix.py", line 247, in open
    raise SerialException(msg.errno, "could not open port {}: {}".format(self._port, msg))
serial.serialutil.SerialException: [Errno 2] could not open port /home/caxenie/dev/ttyUSB1: [Errno 2] No such file or directory: '/home/caxenie/dev/ttyUSB1'
Traceback (most recent call last):
  File "nengo_omnibot_init_arm_dvs.py", line 8, in <module>
    omnirob_arm_cam.connect(nstbot.Serial('/home/caxenie/dev/ttyUSB3', baud=12000000))
  File "/media/data_warehouse/research/devel/neuromorphic_sensorimotor_adaptation/omnirob/nstbot/connection.py", line 4, in __init__
    self.conn = serial.Serial(port, baudrate=baud, rtscts=True, timeout=0)
  File "/usr/local/lib/python2.7/dist-packages/serial/serialutil.py", line 182, in __init__
    self.open()
  File "/usr/local/lib/python2.7/dist-packages/serial/serialposix.py", line 247, in open
    raise SerialException(msg.errno, "could not open port {}: {}".format(self._port, msg))
serial.serialutil.SerialException: [Errno 2] could not open port /home/caxenie/dev/ttyUSB3: [Errno 2] No such file or directory: '/home/caxenie/dev/ttyUSB3'
Traceback (most recent call last):
  File "nengo_omnibot_init_left_dvs.py", line 8, in <module>
Traceback (most recent call last):
  File "nengo_omnibot_init.py", line 12, in <module>
    omnirob_left_cam.connect(nstbot.Serial('/home/caxenie/dev/ttyUSB0', baud=12000000))
      File "/media/data_warehouse/research/devel/neuromorphic_sensorimotor_adaptation/omnirob/nstbot/connection.py", line 4, in __init__
bot.connect(nstbot.Serial('/home/caxenie/dev/ttyUSB2', baud=2000000))
  File "/media/data_warehouse/research/devel/neuromorphic_sensorimotor_adaptation/omnirob/nstbot/connection.py", line 4, in __init__
    self.conn = serial.Serial(port, baudrate=baud, rtscts=True, timeout=0)
      File "/usr/local/lib/python2.7/dist-packages/serial/serialutil.py", line 182, in __init__
self.conn = serial.Serial(port, baudrate=baud, rtscts=True, timeout=0)
      File "/usr/local/lib/python2.7/dist-packages/serial/serialutil.py", line 182, in __init__
self.open()
    self.open()
  File "/usr/local/lib/python2.7/dist-packages/serial/serialposix.py", line 247, in open
  File "/usr/local/lib/python2.7/dist-packages/serial/serialposix.py", line 247, in open
        raise SerialException(msg.errno, "could not open port {}: {}".format(self._port, msg))
raise SerialException(msg.errno, "could not open port {}: {}".format(self._port, msg))
serial.serialutilserial.serialutil..SerialExceptionSerialException: : [Errno 2] could not open port /home/caxenie/dev/ttyUSB0: [Errno 2] No such file or directory: '/home/caxenie/dev/ttyUSB0'[Errno 2] could not open port /home/caxenie/dev/ttyUSB2: [Errno 2] No such file or directory: '/home/caxenie/dev/ttyUSB2'

/media/data_warehouse/research/devel/neuromorphic_sensorimotor_adaptation/omnirob/nstbot/retinabot.py:293: RuntimeWarning: invalid value encountered in double_scalars
  c = sum(ww) * self.track_certainty_scale / dt
/media/data_warehouse/research/devel/neuromorphic_sensorimotor_adaptation/omnirob/nstbot/retinabot.py:293: RuntimeWarning: divide by zero encountered in double_scalars
  c = sum(ww) * self.track_certainty_scale / dt
/media/data_warehouse/research/devel/neuromorphic_sensorimotor_adaptation/omnirob/nstbot/retinabot.py:295: RuntimeWarning: invalid value encountered in double_scalars
  self.track_certainty[i] += (1-decay) * c
/media/data_warehouse/research/devel/neuromorphic_sensorimotor_adaptation/omnirob/nstbot/retinabot.py:293: RuntimeWarning: divide by zero encountered in double_scalars
  c = sum(ww) * self.track_certainty_scale / dt
/media/data_warehouse/research/devel/neuromorphic_sensorimotor_adaptation/omnirob/nstbot/retinabot.py:295: RuntimeWarning: invalid value encountered in double_scalars
  self.track_certainty[i] += (1-decay) * c
/media/data_warehouse/research/devel/neuromorphic_sensorimotor_adaptation/omnirob/nstbot/retinabot.py:293: RuntimeWarning: divide by zero encountered in double_scalars
  c = sum(ww) * self.track_certainty_scale / dt
/media/data_warehouse/research/devel/neuromorphic_sensorimotor_adaptation/omnirob/nstbot/retinabot.py:295: RuntimeWarning: invalid value encountered in double_scalars
  self.track_certainty[i] += (1-decay) * c
